Workbook

Sheet Team Log ins 
A1: SHIPHERO LOG IN CREDENTIALS
A2: Agent Name | B2: Email Address | C2: PASSWORD
A3: Godwin Reasol | B3: teamdani1@proton.me | C3: B6!mY2#vQ9@tL
A4: Claudette Ibong | B4: teamdani2@proton.me | C4: Q8@cN4!zR7$kM
A5: CherryTubongbanua | B5: teamdani3@proton.me | C5: W5#pK9@xT3!vH
A6: Lyra Miclat | B6: teamdani4@proton.me | C6: J7!rM2$yL8@qZ
A7: Joemica Cariño | B7: teamdani5@proton.me | C7: C4@vP9#nX6!kR
A8: Candy Laid | B8: teamdani6@proton.me | C8: F8$zQ3!mT7@wL
A9: Sofhia Mae Santiago | B9: teamdani7@proton.me | C9: L2#xV6@rK9!pN
A10: Dan Mae David | B10: teamdani8@outlook.com | C10: S9!qH4$wM2@zP

Sheet Team Info
A1: Agent Name | B1: Email Address | C1: Contact Number | D1: Birthday | E1: Home Address | F1: Baranggay | G1: Municipality | H1: Province | I1: Zip Code | J1: Landmark
A2: Danielle Ann Mari Crizaldo | B2: daniellecrizaldo781@gmail.com | C2: 9082352381 | D2: 36790 | E2: 005 | F2: Marahan 1 | G2: Alfonso | H2: Cavite | I2: 4123 | J2: Droolymacaroni
A3: Dan Mae David | B3: dnlldvd19@gmail.com | C3: 639665294367 | D3: 34108
A4: Godwin Arellano | B4: ghodwinreasol@gmail.com | C4: 9811265923 | D4: 36816
A5: Candy Laid | B5: laidcandy1@gmail.com | C5: 9190726863 | D5: 31947
A6: Claudette Ibong | B6: blueibong@gmail.com | C6: 9776239411 | D6: 35924
A7: Sofhia Mae Santiago | B7: sofhiamae102099@gmail.com | C7: 9050312839 | D7: 36453
A8: Cherry Rose Tubongbanua | B8: cherryrose201606@gmail.com | C8: 9233005980 | D8: 36668
A9: Lyra Miclat | B9: lyranacu1996@gmail.com | C9: 9754168344 | D9: 35305
A10: Joemica Carino | B10: joemica20@gmail.com | C10: 9630166253 | D10: 34352

Sheet TEAM STATS
A1: 46054
A2: WEEK: February 2 - February 8
A3: Daily Productivity
A4: NAME OF AGENT | B4: Weekly Target | C4: Weekly Actual | D4: 46055 | E4: 46056 | F4: 46057 | G4: 46058 | H4: 46059 | I4: 46060 | J4: 46061 | K4: % Productivity | L4: Final Score
D5: Mon | E5: =text(E4,"ddd") -> Tue | F5: =text(F4,"ddd") -> Wed | G5: =text(G4,"ddd") -> Thu | H5: =text(H4,"ddd") -> Fri | I5: =text(I4,"ddd") -> Sat | J5: =text(J4,"ddd") -> Sun
A6: Danielle Mae David | B6: =30+30+15+20+5+25 -> 125 | C6: =SUM(D6:J6) -> 126 | D6: 33 | E6: 30 | F6: 16 | G6: 18 | H6: 5 | I6: OFF | J6: 24 | K6: =iferror(C6/B6,"-") -> 1.008 | L6: =(IF(K6="",(0),IF(K6>=1,(5),IF(K6>=0.9,(4),IF(K6>=0.8,(3),IF(K6>=0.69,(2),IF(K6<=0.69,(1)))))))) -> 5
A7: Godwin Arellano Reasol | B7: =30+30+25+25+30+20 -> 160 | C7: =SUM(D7:J7) -> 155 | D7: 31 | E7: 27 | F7: 24 | G7: 23 | H7: 32 | I7: OFF | J7: 18 | K7: =iferror(C7/B7,"-") -> 0.96875 | L7: =(IF(K7="",(0),IF(K7>=1,(5),IF(K7>=0.9,(4),IF(K7>=0.8,(3),IF(K7>=0.69,(2),IF(K7<=0.69,(1)))))))) -> 4
A8: Candy Laid | B8: =35+30+35+40+35 -> 175 | C8: =SUM(D8:J8) -> 180 | D8: 36 | E8: OFF | F8: 30 | G8: 42 | H8: 39 | I8: 33 | J8: OFF | K8: =iferror(C8/B8,"-") -> 1.0285714 | L8: =(IF(K8="",(0),IF(K8>=1,(5),IF(K8>=0.9,(4),IF(K8>=0.8,(3),IF(K8>=0.69,(2),IF(K8<=0.69,(1)))))))) -> 5
A9: Mary Claudette Ibong | B9: =35+35+25+25+30+10 -> 160 | C9: =SUM(D9:J9) -> 178 | D9: 42 | E9: 35 | F9: 26 | G9: 37 | H9: 30 | I9: 8 | J9: OFF | K9: =iferror(C9/B9,"-") -> 1.1125 | L9: =(IF(K9="",(0),IF(K9>=1,(5),IF(K9>=0.9,(4),IF(K9>=0.8,(3),IF(K9>=0.69,(2),IF(K9<=0.69,(1)))))))) -> 5
A10: Sofhia Mae Santiago | B10: =30+25+30 -> 85 | C10: =SUM(D10:J10) -> 85 | D10: 32 | E10: 26 | F10: 27 | G10: OFF | H10: OFF | I10: LWOP | J10: LWOP | K10: =iferror(C10/B10,"-") -> 1 | L10: =(IF(K10="",(0),IF(K10>=1,(5),IF(K10>=0.9,(4),IF(K10>=0.8,(3),IF(K10>=0.69,(2),IF(K10<=0.69,(1)))))))) -> 5
A11: Cherry Tubongbanua | B11: =30+30+25+25+40+25 -> 175 | C11: =SUM(D11:J11) -> 176 | D11: 29 | E11: 31 | F11: 20 | G11: 26 | H11: OFF | I11: 44 | J11: 26 | K11: =iferror(C11/B11,"-") -> 1.0057143 | L11: =(IF(K11="",(0),IF(K11>=1,(5),IF(K11>=0.9,(4),IF(K11>=0.8,(3),IF(K11>=0.69,(2),IF(K11<=0.69,(1)))))))) -> 5
A12: Faith Rivera | B12: =20*6 -> 120 | C12: =SUM(D12:J12) -> 119 | D12: 21 | E12: 20 | F12: 17 | G12: 19 | H12: 22 | I12: 20 | J12: OFF | K12: =iferror(C12/B12,"-") -> 0.99166667 | L12: =(IF(K12="",(0),IF(K12>=1,(5),IF(K12>=0.9,(4),IF(K12>=0.8,(3),IF(K12>=0.69,(2),IF(K12<=0.69,(1)))))))) -> 4
A14: Weekly Call Stats
A15: NAME OF AGENT | B15: Ringing Attempts | C15: Picked Up | D15: Not Picked Up | E15: Picked Up Rate | F15: AHT | G15: Picked Up Rate Score | H15: AHT Rate Score
A17: Danielle Mae David | B17: 130 | C17: 126 | D17: =B17-C17 -> 4 | E17: =IFERROR(C17/B17,"") -> 0.96923077 | F17: 0.0023611111 | G17: =IFERROR((IF(E17="",(0),IF(E17>=0.98,(5),IF(E17>=0.95,(4.5),IF(E17>=0.9,(4),IF(E17>=0.8,(3),IF(E17<=0.69,(1)))))))),"") -> 4.5 | H17: =ROUND( IF(F17="", 0, MAX(1, 5 - MAX(0, (F17 - TIME(0,4,0)) / TIME(0,1,0) * 0.5)) ), 2 ) -> 5
A18: Godwin Arellano Reasol | B18: 155 | C18: 154 | D18: =B18-C18 -> 1 | E18: =IFERROR(C18/B18,"") -> 0.99354839 | F18: 0.0039699074 | G18: =IFERROR((IF(E18="",(0),IF(E18>=0.98,(5),IF(E18>=0.95,(4.5),IF(E18>=0.9,(4),IF(E18>=0.8,(3),IF(E18<=0.69,(1)))))))),"") -> 5 | H18: =ROUND( IF(F18="", 0, MAX(1, 5 - MAX(0, (F18 - TIME(0,6,0)) / TIME(0,1,0) * 0.5)) ), 2 ) -> 5
A19: Candy Laid | B19: 178 | C19: 174 | D19: =B19-C19 -> 4 | E19: =IFERROR(C19/B19,"") -> 0.97752809 | F19: 0.0032175926 | G19: =IFERROR((IF(E19="",(0),IF(E19>=0.98,(5),IF(E19>=0.95,(4.5),IF(E19>=0.9,(4),IF(E19>=0.8,(3),IF(E19<=0.69,(1)))))))),"") -> 4.5 | H19: =ROUND( IF(F19="", 0, MAX(1, 5 - MAX(0, (F19 - TIME(0,4,0)) / TIME(0,1,0) * 0.5)) ), 2 ) -> 4.68
A20: Mary Claudette Ibong | B20: 183 | C20: 180 | D20: =B20-C20 -> 3 | E20: =IFERROR(C20/B20,"") -> 0.98360656 | F20: 0.0031944444 | G20: =IFERROR((IF(E20="",(0),IF(E20>=0.98,(5),IF(E20>=0.95,(4.5),IF(E20>=0.9,(4),IF(E20>=0.8,(3),IF(E20<=0.69,(1)))))))),"") -> 5 | H20: =ROUND( IF(F20="", 0, MAX(1, 5 - MAX(0, (F20 - TIME(0,6,0)) / TIME(0,1,0) * 0.5)) ), 2 ) -> 5
A21: Sofhia Mae Santiago | B21: 90 | C21: 89 | D21: =B21-C21 -> 1 | E21: =IFERROR(C21/B21,"") -> 0.98888889 | F21: 0.0030787037 | G21: =IFERROR((IF(E21="",(0),IF(E21>=0.98,(5),IF(E21>=0.95,(4.5),IF(E21>=0.9,(4),IF(E21>=0.8,(3),IF(E21<=0.69,(1)))))))),"") -> 5 | H21: =ROUND( IF(F21="", 0, MAX(1, 5 - MAX(0, (F21 - TIME(0,4,0)) / TIME(0,1,0) * 0.5)) ), 2 ) -> 4.78
A22: Cherry Tubongbanua | B22: 172 | C22: 172 | D22: =B22-C22 -> 0 | E22: =IFERROR(C22/B22,"") -> 1 | F22: 0.0033333333 | G22: =IFERROR((IF(E22="",(0),IF(E22>=0.98,(5),IF(E22>=0.95,(4.5),IF(E22>=0.9,(4),IF(E22>=0.8,(3),IF(E22<=0.69,(1)))))))),"") -> 5 | H22: =ROUND( IF(F22="", 0, MAX(1, 5 - MAX(0, (F22 - TIME(0,7,0)) / TIME(0,1,0) * 0.5)) ), 2 ) -> 5
A23: Faith Rivera | B23: 119 | C23: 116 | D23: =B23-C23 -> 3 | E23: =IFERROR(C23/B23,"") -> 0.97478992 | F23: 0.0044907407 | G23: =IFERROR((IF(E23="",(0),IF(E23>=0.98,(5),IF(E23>=0.95,(4.5),IF(E23>=0.9,(4),IF(E23>=0.8,(3),IF(E23<=0.69,(1)))))))),"") -> 4.5 | H23: =ROUND( IF(F23="", 0, MAX(1, 5 - MAX(0, (F23 - TIME(0,8,0)) / TIME(0,1,0) * 0.5)) ), 2 ) -> 5
A24: Danielle Crizaldo | B24: 19 | C24: 19 | D24: =B24-C24 -> 0 | E24: =IFERROR(C24/B24,"") -> 1 | F24: 0.0015972222 | G24: =IFERROR((IF(E24="",(0),IF(E24>=0.98,(5),IF(E24>=0.95,(4.5),IF(E24>=0.9,(4),IF(E24>=0.8,(3),IF(E24<=0.69,(1)))))))),"") -> 5 | H24: =ROUND( IF(F24="", 0, MAX(1, 5 - MAX(0, (F24 - TIME(0,8,0)) / TIME(0,1,0) * 0.5)) ), 2 ) -> 5
A26: Team Initial Scorecard
A27: CSR NAME | B27: Overall QA Spotcheck 40% | C27: QA Jacky Spotcheck 30% | D27: TL Spotcheck 10% | E27: Productivity 30% | F27: PRODUCTIVITY AVERAGE
A28: Dan Mae David | B28: =(C28*0.3)+(D28*0.1) -> #REF! | C28: 1 | D28: =#REF! -> #REF! | E28: =(L6+G17+H17)/15*0.3 -> 0.29 | F28: =(E28/30%)*10 -> 9.6666667
A29: Godwin Reasol | B29: =(C29*0.3)+(D29*0.1) -> #REF! | C29: 1 | D29: =#REF! -> #REF! | E29: =(L7+G18+H18)/15*0.3 -> 0.28 | F29: =(E29/30%)*10 -> 9.3333333
A30: Candy Laid | B30: =(C30*0.3)+(D30*0.1) -> #REF! | C30: 1 | D30: =#REF! -> #REF! | E30: =(L8+G19+H19)/15*0.3 -> 0.2836 | F30: =(E30/30%)*10 -> 9.4533333
A31: Claudette Ibong | B31: =(C31*0.3)+(D31*0.1) -> #REF! | C31: 1 | D31: =#REF! -> #REF! | E31: =(L9+G20+H20)/15*0.3 -> 0.3 | F31: =(E31/30%)*10 -> 10
A32: Sofhia Santiago | B32: =(C32*0.3)+(D32*0.1) -> #REF! | C32: 1 | D32: =#REF! -> #REF! | E32: =(L10+G21+H21)/15*0.3 -> 0.2956 | F32: =(E32/30%)*10 -> 9.8533333
A33: Cherry Tubongbanua | B33: =(C33*0.3)+(D33*0.1) -> #REF! | C33: 1 | D33: =#REF! -> #REF! | E33: =(L11+G22+H22)/15*0.3 -> 0.3 | F33: =(E33/30%)*10 -> 10
A34: Faith Rivera | B34: =(C34*0.3)+(D34*0.1) -> #REF! | C34: 0.71 | D34: =Faith!D54 -> #REF! | E34: =(L12+G23+H23)/15*0.3 -> 0.27 | F34: =(E34/30%)*10 -> 9
A36: OT HOURS for Payroll
A37: CSR NAME | B37: Authorized OT | C37: 46055 | D37: 46056 | E37: 46057 | F37: 46058 | G37: 46059 | H37: 46060 | I37: 46061
C38: Mon | D38: Tue | E38: Wed | F38: Thu | G38: Fri | H38: Sat | I38: Sun
A39: Dan Mae David | B39: =Sum(C39:I39) -> 8 | G39: 8
A40: Godwin Reasol | B40: =Sum(C40:I40) -> 14 | C40: 2 | E40: 2 | G40: 2 | I40: 8
A41: Candy Laid | B41: =Sum(C41:I41) -> 6 | F41: 2 | G41: 2 | H41: 2
A42: Claudette Ibong | B42: =Sum(C42:I42) -> 12 | D42: 2 | F42: 2 | H42: 8
A43: Sofhia Santiago | B43: =Sum(C43:I43) -> 6 | C43: 2 | D43: 2 | E43: 2
A44: Cherry Tubongbanua | B44: =Sum(C44:I44) -> 12 | D44: 2 | F44: 8 | H44: 2
...

Sheet Daily and Weekly Call Stats
B1: WEEK: August 3,2026 - August 9,2026
B2: Daily Productivity Record
A3: Name of Agent | B3: Weekly Target | C3: Actual Productivity | D3: 46237 | E3: 46238 | F3: 46239 | G3: 46240 | H3: 46241 | I3: 46242 | J3: 46243 | K3: Productivity % | L3: Final Score
D4: =text(D3,"ddd") -> Mon | E4: =text(E3,"ddd") -> Tue | F4: =text(F3,"ddd") -> Wed | G4: =text(G3,"ddd") -> Thu | H4: =text(H3,"ddd") -> Fri | I4: =text(I3,"ddd") -> Sat | J4: =text(J3,"ddd") -> Sun
A5: Daniellel Mae David | B5: =30*5 -> 150 | C5: =SUM(D5:J5) -> 158 | D5: 24 | E5: 31 | F5: 28 | G5: 25 | H5: 44 | I5: 6 | J5: OFF | K5: =iferror(C5/B5,"-") -> 1.0533333 | L5: =(IF(K5="",(0),IF(K5>=1,(5),IF(K5>=0.9,(4),IF(K5>=0.8,(3),IF(K5>=0.69,(2),IF(K5<=0.69,(1)))))))) -> 5
A6: Godwin Arellano Reasol | B6: =30*4+15 -> 135 | C6: =SUM(D6:J6) -> 124 | D6: 29 | E6: 21 | F6: 24 | G6: 14 | H6: 28 | I6: OFF | J6: 8 | K6: =iferror(C6/B6,"-") -> 0.91851852 | L6: =(IF(K6="",(0),IF(K6>=1,(5),IF(K6>=0.9,(4),IF(K6>=0.8,(3),IF(K6>=0.69,(2),IF(K6<=0.69,(1)))))))) -> 4
A7: Candy Laid | B7: =30*5 -> 150 | C7: =SUM(D7:J7) -> 168 | D7: 33 | E7: 28 | F7: OFF | G7: 36 | H7: 38 | I7: 33 | J7: OFF | K7: =iferror(C7/B7,"-") -> 1.12 | L7: =(IF(K7="",(0),IF(K7>=1,(5),IF(K7>=0.9,(4),IF(K7>=0.8,(3),IF(K7>=0.69,(2),IF(K7<=0.69,(1)))))))) -> 5
A8: Mary Claudette Ibong | B8: =30*3+15+20 -> 125 | C8: =SUM(D8:J8) -> 114 | D8: 26 | E8: 23 | F8: 18 | G8: 13 | H8: OFF | I8: 17 | J8: 17 | K8: =iferror(C8/B8,"-") -> 0.912 | L8: =(IF(K8="",(0),IF(K8>=1,(5),IF(K8>=0.9,(4),IF(K8>=0.8,(3),IF(K8>=0.69,(2),IF(K8<=0.69,(1)))))))) -> 4
A9: Sofhia Mae Santiago | B9: =30*4+20 -> 140 | C9: =SUM(D9:J9) -> 128 | D9: 34 | E9: 24 | F9: 27 | G9: 8 | H9: OFF | I9: 16 | J9: 19 | K9: =iferror(C9/B9,"-") -> 0.91428571 | L9: =(IF(K9="",(0),IF(K9>=1,(5),IF(K9>=0.9,(4),IF(K9>=0.8,(3),IF(K9>=0.69,(2),IF(K9<=0.69,(1)))))))) -> 4
A10: Cherry Tubongbanua | B10: =30*5 -> 150 | C10: =SUM(D10:J10) -> 179 | D10: 33 | E10: 36 | F10: 32 | G10: 41 | H10: 27 | I10: 10 | J10: OFF | K10: =iferror(C10/B10,"-") -> 1.1933333 | L10: =(IF(K10="",(0),IF(K10>=1,(5),IF(K10>=0.9,(4),IF(K10>=0.8,(3),IF(K10>=0.69,(2),IF(K10<=0.69,(1)))))))) -> 5
A11: Lyra Miclat | B11: =30*5 -> 150 | C11: =SUM(D11:J11) -> 162 | D11: 39 | E11: 27 | F11: 42 | G11: 28 | H11: 26 | I11: OFF | J11: OFF | K11: =iferror(C11/B11,"-") -> 1.08 | L11: =(IF(K11="",(0),IF(K11>=1,(5),IF(K11>=0.9,(4),IF(K11>=0.8,(3),IF(K11>=0.69,(2),IF(K11<=0.69,(1)))))))) -> 5
A12: Joemica Carino | B12: =30*3+20+15 -> 125 | C12: =SUM(D12:J12) -> 116 | D12: 18 | E12: 14 | F12: OFF | G12: 26 | H12: 29 | I12: 17 | J12: 12 | K12: =iferror(C12/B12,"-") -> 0.928 | L12: =(IF(K12="",(0),IF(K12>=1,(5),IF(K12>=0.9,(4),IF(K12>=0.8,(3),IF(K12>=0.69,(2),IF(K12<=0.69,(1)))))))) -> 4
B14: Weekly Call Stats
A15: Name of Agent | B15: Ringing Attempts | C15: Picked Up | D15: Not Picked Up | E15: Picked Up Rate | F15: AHT | G15: Picked Up Rate Score | H15: AHT Score
A17: Daniellel Mae David | B17: 167 | C17: 158 | D17: =B17-C17 -> 9 | E17: =Iferror(C17/B17,"") -> 0.94610778 | F17: 0.0018865741 | G17: =IFERROR((IF(E17="",(0),IF(E17>=0.98,(5),IF(E17>=0.95,(4.5),IF(E17>=0.9,(4),IF(E17>=0.8,(3),IF(E17<=0.69,(1)))))))),"") -> 4 | H17: =ROUND( IF(F17="", 0, MAX(1, 5 - MAX(0, (F17 - TIME(0,4,0)) / TIME(0,1,0) * 0.5)) ), 2 ) -> 5
A18: Godwin Arellano Reasol | B18: 127 | C18: 124 | D18: =B18-C18 -> 3 | E18: =Iferror(C18/B18,"") -> 0.97637795 | F18: 0.0039467593 | G18: =IFERROR((IF(E18="",(0),IF(E18>=0.98,(5),IF(E18>=0.95,(4.5),IF(E18>=0.9,(4),IF(E18>=0.8,(3),IF(E18<=0.69,(1)))))))),"") -> 4.5 | H18: =ROUND( IF(F18="", 0, MAX(1, 5 - MAX(0, (F18 - TIME(0,4,0)) / TIME(0,1,0) * 0.5)) ), 2 ) -> 4.16
A19: Candy Laid | B19: 181 | C19: 176 | D19: =B19-C19 -> 5 | E19: =Iferror(C19/B19,"") -> 0.97237569 | F19: 0.0034722222 | G19: =IFERROR((IF(E19="",(0),IF(E19>=0.98,(5),IF(E19>=0.95,(4.5),IF(E19>=0.9,(4),IF(E19>=0.8,(3),IF(E19<=0.69,(1)))))))),"") -> 4.5 | H19: =ROUND( IF(F19="", 0, MAX(1, 5 - MAX(0, (F19 - TIME(0,4,0)) / TIME(0,1,0) * 0.5)) ), 2 ) -> 4.5
A20: Mary Claudette Ibong | B20: 115 | C20: 114 | D20: =B20-C20 -> 1 | E20: =Iferror(C20/B20,"") -> 0.99130435 | F20: 0.0035416667 | G20: =IFERROR((IF(E20="",(0),IF(E20>=0.98,(5),IF(E20>=0.95,(4.5),IF(E20>=0.9,(4),IF(E20>=0.8,(3),IF(E20<=0.69,(1)))))))),"") -> 5 | H20: =ROUND( IF(F20="", 0, MAX(1, 5 - MAX(0, (F20 - TIME(0,4,0)) / TIME(0,1,0) * 0.5)) ), 2 ) -> 4.45
A21: Sofhia Mae Santiago | B21: 131 | C21: 128 | D21: =B21-C21 -> 3 | E21: =Iferror(C21/B21,"") -> 0.97709924 | F21: 0.0024189815 | G21: =IFERROR((IF(E21="",(0),IF(E21>=0.98,(5),IF(E21>=0.95,(4.5),IF(E21>=0.9,(4),IF(E21>=0.8,(3),IF(E21<=0.69,(1)))))))),"") -> 4.5 | H21: =ROUND( IF(F21="", 0, MAX(1, 5 - MAX(0, (F21 - TIME(0,4,0)) / TIME(0,1,0) * 0.5)) ), 2 ) -> 5
A22: Cherry Tubongbanua | B22: 180 | C22: 179 | D22: =B22-C22 -> 1 | E22: =Iferror(C22/B22,"") -> 0.99444444 | F22: 0.0046180556 | G22: =IFERROR((IF(E22="",(0),IF(E22>=0.98,(5),IF(E22>=0.95,(4.5),IF(E22>=0.9,(4),IF(E22>=0.8,(3),IF(E22<=0.69,(1)))))))),"") -> 5 | H22: =ROUND( IF(F22="", 0, MAX(1, 5 - MAX(0, (F22 - TIME(0,4,0)) / TIME(0,1,0) * 0.5)) ), 2 ) -> 3.68
A23: Lyra Miclat | B23: 186 | C23: 176 | D23: =B23-C23 -> 10 | E23: =Iferror(C23/B23,"") -> 0.94623656 | F23: 0.0033101852 | G23: =IFERROR((IF(E23="",(0),IF(E23>=0.98,(5),IF(E23>=0.95,(4.5),IF(E23>=0.9,(4),IF(E23>=0.8,(3),IF(E23<=0.69,(1)))))))),"") -> 4 | H23: =ROUND( IF(F23="", 0, MAX(1, 5 - MAX(0, (F23 - TIME(0,4,0)) / TIME(0,1,0) * 0.5)) ), 2 ) -> 4.62
A24: Joemica Carino | B24: 121 | C24: 116 | D24: =B24-C24 -> 5 | E24: =Iferror(C24/B24,"") -> 0.95867769 | F24: 0.0036574074 | G24: =IFERROR((IF(E24="",(0),IF(E24>=0.98,(5),IF(E24>=0.95,(4.5),IF(E24>=0.9,(4),IF(E24>=0.8,(3),IF(E24<=0.69,(1)))))))),"") -> 4.5 | H24: =ROUND( IF(F24="", 0, MAX(1, 5 - MAX(0, (F24 - TIME(0,4,0)) / TIME(0,1,0) * 0.5)) ), 2 ) -> 4.37
B27: Score per Metrics for Scorecard (Initial Productivity and QA Scores) | H27: What Does 30% Productivity Covers?
A28: Name of Agent | B28: QA JACKY SCORE 30% | C28: QA TL SCORE 10% | D28: Final QA Score 40% | E28: Productivity (WORK ETHIC) % (30%) | F28: FINAL Work Ethic Score | H28: 1. Final Score from Daily Productivity Record
H29: 2. Picked Up Rate Score
A30: Daniellel Mae David | B30: 1 | C30: =Dan!D90 -> 1 | D30: =(B30*0.3)+(C30*0.1) -> 0.4 | E30: =(L5+G17+H17)/15*0.3 -> 0.28 | F30: =(E30/30%)*10 -> 9.3333333 | H30: 3.. AHT Score
A31: Godwin Arellano Reasol | B31: 1 | C31: =Godwin!D72 -> 1 | D31: =(B31*0.3)+(C31*0.1) -> 0.4 | E31: =(L6+G18+H18)/15*0.3 -> 0.2532 | F31: =(E31/30%)*10 -> 8.44
A32: Candy Laid | B32: 1 | C32: =Candy!D72 -> 1 | D32: =(B32*0.3)+(C32*0.1) -> 0.4 | E32: =(L7+G19+H19)/15*0.3 -> 0.28 | F32: =(E32/30%)*10 -> 9.3333333 | H32: Computation:
A33: Mary Claudette Ibong | B33: 1 | C33: =Claudette!D54 -> 1 | D33: =(B33*0.3)+(C33*0.1) -> 0.4 | E33: =(L8+G20+H20)/15*0.3 -> 0.269 | F33: =(E33/30%)*10 -> 8.9666667 | H33: Final Productivity % | J33: (Final productivity Score + Picked Up Rate Score + AHT Score) /15 *.30
A34: Sofhia Mae Santiago | B34: 0.85 | C34: =Sofhia!D54 -> 1 | D34: =(B34*0.3)+(C34*0.1) -> 0.355 | E34: =(L9+G21+H21)/15*0.3 -> 0.27 | F34: =(E34/30%)*10 -> 9 | H34: Productivity Score | J34: (Final Productivity % / 30%) *10
A35: Cherry Tubongbanua | B35: 1 | C35: =Cherry!D36 -> 1 | D35: =(B35*0.3)+(C35*0.1) -> 0.4 | E35: =(L10+G22+H22)/15*0.3 -> 0.2736 | F35: =(E35/30%)*10 -> 9.12
A36: Lyra Miclat | B36: 0.25 | C36: =Lyra!D503 -> 1 | D36: =(B36*0.3)+(C36*0.1) -> 0.175 | E36: =(L11+G23+H23)/15*0.3 -> 0.2724 | F36: =(E36/30%)*10 -> 9.08
A37: Joemica Carino | B37: 1 | C37: =Mikka!D448 -> 1 | D37: =(B37*0.3)+(C37*0.1) -> 0.4 | E37: =(L12+G24+H24)/15*0.3 -> 0.2574 | F37: =(E37/30%)*10 -> 8.58
B38: WEEK: August 10,2026 - August 16,2026
B39: Daily Productivity Record
A40: Name of Agent | B40: Weekly Target | C40: Actual Productivity | D40: 46244 | E40: 46245 | F40: 46246 | G40: 46247 | H40: 46248 | I40: 46249 | J40: 46250 | K40: Productivity % | L40: Final Score
D41: =text(D40,"ddd") -> Mon | E41: =text(E40,"ddd") -> Tue | F41: =text(F40,"ddd") -> Wed | G41: =text(G40,"ddd") -> Thu | H41: =text(H40,"ddd") -> Fri | I41: =text(I40,"ddd") -> Sat | J41: =text(J40,"ddd") -> Sun
A42: Daniellel Mae David | B42: =30*5 -> 150 | C42: =SUM(D42:J42) -> 155 | D42: 28 | E42: 22 | F42: 32 | G42: 29 | H42: 35 | I42: 9 | J42: OFF | K42: =iferror(C42/B42,"-") -> 1.0333333 | L42: =(IF(K42="",(0),IF(K42>=1,(5),IF(K42>=0.9,(4),IF(K42>=0.8,(3),IF(K42>=0.69,(2),IF(K42<=0.69,(1)))))))) -> 5
A43: Godwin Arellano Reasol | B43: =30*4+15+25 -> 160 | C43: =SUM(D43:J43) -> 143 | D43: 25 | E43: 27 | F43: 21 | G43: 30 | H43: 29 | I43: OFF | J43: 11 | K43: =iferror(C43/B43,"-") -> 0.89375 | L43: =(IF(K43="",(0),IF(K43>=1,(5),IF(K43>=0.9,(4),IF(K43>=0.8,(3),IF(K43>=0.69,(2),IF(K43<=0.69,(1)))))))) -> 3
A44: Candy Laid | B44: =30*5+15 -> 165 | C44: =SUM(D44:J44) -> 176 | D44: 39 | E44: 28 | F44: OFF | G44: 38 | H44: 25 | I44: 34 | J44: 12 | K44: =iferror(C44/B44,"-") -> 1.0666667 | L44: =(IF(K44="",(0),IF(K44>=1,(5),IF(K44>=0.9,(4),IF(K44>=0.8,(3),IF(K44>=0.69,(2),IF(K44<=0.69,(1)))))))) -> 5
...

Sheet WEEKLY SCORECARD
B1: WEEK:January 26 ,2026 - February 1,2026
B2: Danielle David | C2: Godwin Reasol | D2: Candy Laid | E2: Claudette Ibong | F2: Sofhia Santiago | G2: Cherry Tubongbanua
A3: Week Ending | B3: WEEK: January 26 ,2026 - February 1,2026
A4: ATTENDANCE
A5: Hours Worked | B5: 47.24 | C5: 44 | D5: 46 | E5: 51.93 | F5: 43.54 | G5: 52.44
A6: Hours Scheduled | B6: 40 | C6: 40 | D6: 40 | E6: 40 | F6: 40 | G6: 40
A7: Attendance % | B7: =B5/B6 -> 1.181 | C7: =C5/C6 -> 1.1 | D7: =D5/D6 -> 1.15 | E7: =E5/E6 -> 1.29825 | F7: =F5/F6 -> 1.0885 | G7: =G5/G6 -> 1.311
A8: QUALITY
A9: QA Score | B9: 40 | C9: 39.90 | D9: 37.40 | E9: 40 | F9: 40 | G9: 40
A10: QA Max | B10: 40 | C10: 40 | D10: 40 | E10: 40 | F10: 40 | G10: 40
A11: Quality % | B11: =B9/B10 -> 1 | C11: =C9/C10 -> 0.9975 | D11: =D9/D10 -> 0.935 | E11: =E9/E10 -> 1 | F11: =F9/F10 -> 1 | G11: =G9/G10 -> 1
A12: PRODUCTIVITY
A13: Shift | B13: MID | C13: AM | D13: AM | E13: AM | F13: AM | G13: MID
A14: Team Assignment' | B14: Other Brands | C14: Oricle | D14: Other Brands | E14: Oricle | F14: Other Brands | G14: Oricle
A15: Call Target # | B15: =IF(B5<B6,B6,B5) * IF(B13="AM", IF(B14="Oricle",4, IF(B14="Other Brands",3, IF(B14="Oricle Prio",0.6,""))), IF(B13="MID", IF(B14="Oricle",2.5, IF(B14="Other Brands",3, IF(B14="Oricle Prio",0.6,""))), IF(B13="GY", IF(B14="Oricle",0.9, IF(B14="Other Brands",0.9, IF(B14="Oricle Prio",0.3,""))),"")))-17 -> 124.72 | C15: =IF(C5<C6,C6,C5) * IF(C13="AM", IF(C14="Oricle",4, IF(C14="Other Brands",3, IF(C14="Oricle Prio",0.6,""))), IF(C13="MID", IF(C14="Oricle",2.5, IF(C14="Other Brands",3, IF(C14="Oricle Prio",0.6,""))), IF(C13="GY", IF(C14="Oricle",0.9, IF(C14="Other Brands",0.9, IF(C14="Oricle Prio",0.3,""))),""))) -> 176 | D15: =IF(D5<D6,D6,D5) * IF(D13="AM", IF(D14="Oricle",4, IF(D14="Other Brands",3, IF(D14="Oricle Prio",0.6,""))), IF(D13="MID", IF(D14="Oricle",2.5, IF(D14="Other Brands",3, IF(D14="Oricle Prio",0.6,""))), IF(D13="GY", IF(D14="Oricle",0.9, IF(D14="Other Brands",0.9, IF(D14="Oricle Prio",0.3,""))),""))) -> 138 | E15: =IF(E5<E6,E6,E5) * IF(E13="AM", IF(E14="Oricle",4, IF(E14="Other Brands",3, IF(E14="Oricle Prio",0.6,""))), IF(E13="MID", IF(E14="Oricle",2.5, IF(E14="Other Brands",3, IF(E14="Oricle Prio",0.6,""))), IF(E13="GY", IF(E14="Oricle",0.9, IF(E14="Other Brands",0.9, IF(E14="Oricle Prio",0.3,""))),""))) -> 207.72 | F15: =IF(F5<F6,F6,F5) * IF(F13="AM", IF(F14="Oricle",4, IF(F14="Other Brands",3, IF(F14="Oricle Prio",0.6,""))), IF(F13="MID", IF(F14="Oricle",2.5, IF(F14="Other Brands",3, IF(F14="Oricle Prio",0.6,""))), IF(F13="GY", IF(F14="Oricle",0.9, IF(F14="Other Brands",0.9, IF(F14="Oricle Prio",0.3,""))),""))) -> 130.62 | G15: =IF(G5<G6,G6,G5) * IF(G13="AM", IF(G14="Oricle",4, IF(G14="Other Brands",3, IF(G14="Oricle Prio",0.6,""))), IF(G13="MID", IF(G14="Oricle",2.5, IF(G14="Other Brands",3, IF(G14="Oricle Prio",0.6,""))), IF(G13="GY", IF(G14="Oricle",0.9, IF(G14="Other Brands",0.9, IF(G14="Oricle Prio",0.3,""))),""))) -> 131.1
A16: Total Call # | B16: 144 | C16: 119 | D16: 137 | E16: 187 | F16: 171 | G16: 129
A17: Call Pick Up # | B17: 141 | C17: 119 | D17: 131 | E17: 183 | F17: 169 | G17: 129
A18: Pick Up % | B18: =IF(B16>0,B17/B16,0) -> 0.97916667 | C18: =IF(C16>0,C17/C16,0) -> 1 | D18: =IF(D16>0,D17/D16,0) -> 0.95620438 | E18: =IF(E16>0,E17/E16,0) -> 0.97860963 | F18: =IF(F16>0,F17/F16,0) -> 0.98830409 | G18: =IF(G16>0,G17/G16,0) -> 1 | H18: =IF(H16>0,H17/H16,0) -> 0
A19: Target Completion% | B19: =IF(B15>0,B17/B15,0) -> 1.1305324 | C19: =IF(C15>0,C17/C15,0) -> 0.67613636 | D19: =IF(D15>0,D17/D15,0) -> 0.94927536 | E19: =IF(E15>0,E17/E15,0) -> 0.88099365 | F19: =IF(F15>0,F17/F15,0) -> 1.2938294 | G19: =IF(G15>0,G17/G15,0) -> 0.98398169 | H19: =IF(H15>0,H17/H15,0) -> 0
A20: Productivity % | B20: =average(B18:B19) -> 1.0548495 | C20: =average(C18:C19) -> 0.83806818 | D20: =average(D18:D19) -> 0.95273987 | E20: =average(E18:E19) -> 0.92980164 | F20: =average(F18:F19) -> 1.1410668 | G20: =average(G18:G19) -> 0.99199085 | H20: =average(H18:H19) -> 0
A21: WORK ETHIC (10 pts)
A22: Work Ethic Score | B22: 10 | C22: 9.33 | D22: 8.77 | E22: 9.66 | F22: 8.93 | G22: 9.33 | H22: 9.33
A23: Work Ethic Max | B23: 10 | C23: 10 | D23: 10 | E23: 10 | F23: 10 | G23: 10 | H23: 10
A24: Work Ethic % | B24: =IF(B22=0,0,B22/B23) -> 1 | C24: =IF(C22=0,0,C22/C23) -> 0.933 | D24: =IF(D22=0,0,D22/D23) -> 0.877 | E24: =IF(E22=0,0,E22/E23) -> 0.966 | F24: =IF(F22=0,0,F22/F23) -> 0.893 | G24: =IF(G22=0,0,G22/G23) -> 0.933 | H24: =IF(H22=0,0,H22/H23) -> 0.933
A25: INFRACTIONS (-10 pts)
A26: Number of Infractions | B26: 0 | C26: 0 | D26: 0 | E26: 0 | F26: 0 | G26: 0 | H26: 0
A27: FINAL SCORE
A28: Attendance Weighted (25%) | B28: =B7*25 -> 29.525 | C28: =C7*25 -> 27.5 | D28: =D7*25 -> 28.75 | E28: =E7*25 -> 32.45625 | F28: =F7*25 -> 27.2125 | G28: =G7*25 -> 32.775 | H28: =H7*25 -> 0
A29: Quality Weighted (35%) | B29: =B11*35 -> 35 | C29: =C11*35 -> 34.9125 | D29: =D11*35 -> 32.725 | E29: =E11*35 -> 35 | F29: =F11*35 -> 35 | G29: =G11*35 -> 35 | H29: =H11*35 -> 0
A30: Productivity Weighted (25%) | B30: =if(B7<100%,B20*25,B20*30) -> 31.645486 | C30: =if(C7<100%,C20*25,C20*30) -> 25.142045 | D30: =if(D7<100%,D20*25,D20*30) -> 28.582196 | E30: =if(E7<100%,E20*25,E20*30) -> 27.894049 | F30: =if(F7<100%,F20*25,F20*30) -> 34.232003 | G30: =if(G7<100%,G20*25,G20*30) -> 29.759725 | H30: =if(H7<100%,H20*25,H20*30) -> 0
A31: Work Ethic Weighted (15%) | B31: =B24*15 -> 15 | C31: =C24*15 -> 13.995 | D31: =D24*15 -> 13.155 | E31: =E24*15 -> 14.49 | F31: =F24*15 -> 13.395 | G31: =G24*15 -> 13.995 | H31: =H24*15 -> 13.995
A32: Infractions Penalty | B32: =B26*-10 -> 0 | C32: =C26*-10 -> 0 | D32: =D26*-10 -> 0 | E32: =E26*-10 -> 0 | F32: =F26*-10 -> 0 | G32: =G26*-10 -> 0 | H32: =H26*-10 -> 0
A33: TOTAL SCORE (out of 100) | B33: =B28+B29+B30+B31+B32 -> 111.17049 | C33: =C28+C29+C30+C31+C32 -> 101.54955 | D33: =D28+D29+D30+D31+D32 -> 103.2122 | E33: =E28+E29+E30+E31+E32 -> 109.8403 | F33: =F28+F29+F30+F31+F32 -> 109.8395 | G33: =G28+G29+G30+G31+G32 -> 111.52973 | H33: =H28+H29+H30+H31+H32 -> 13.995
A34: Overall % | B34: =B33/100 -> 1.1117049 | C34: =C33/100 -> 1.0154955 | D34: =D33/100 -> 1.032122 | E34: =E33/100 -> 1.098403 | F34: =F33/100 -> 1.098395 | G34: =G33/100 -> 1.1152973 | H34: =H33/100 -> 0.13995
A35: TEAM RANKING | B35: Good | C35: Good | D35: Good | E35: Good | F35: Good | G35: Top Performer | H35: Low Performer
A36: COMMENTS/ISSUES | H36: -CSR struggles on searching fo the customer's target which prolongs the call. Aside from this, CSR failed to provide proper resolution on some call tickets
A37: ~````````````````````
B38: WEEK: February 2 ,2026 - February 8,2026
B39: Danielle David | C39: Godwin Reasol | D39: Candy Laid | E39: Claudette Ibong | F39: Sofhia Santiago | G39: Cherry Tubongbanua
A40: Week Ending | B40: WEEK: February 2 ,2026 - February 8,2026
...

Sheet Dan
A1: Week (July 6, - July 12,2026)
A2: Ticket Link | B2: Date | C2: Day | D2: SCORE | E2: Notes and Tagging(internal Note and Sticky Note) 5% | F2: COURTESY & EMPATHY 15% | G2: TONE OF VOICE & ELOQUENCE 20% | H2: CALL CONTROL 15% | I2: VERIFICATION 5% | J2: PROBING 5% | K2: MASTERY OF INFORMATION 15% | L2: RESOLUTION 20% | M2: Average | N2: NOTES
A3: https://4ammedia.zendesk.com/agent/tickets/211886 | B3: 46209 | C3: =IF(B3="", "", TEXT(B3, "ddd")) -> Mon | D3: =IF(E3="Yes",0.05,0) +IF(F3="Yes",0.1,0) +IF(G3="Yes",0.15,0) +IF(H3="Yes",0.15,0) +IF(I3="Yes",0.05,0) +IF(J3="Yes",0.05,0) +IF(K3="Yes",0.15,0) +IF(L3="Yes",0.3,0) -> 1 | E3: Yes | F3: Yes | G3: Yes | H3: Yes | I3: Yes | J3: Yes | K3: Yes | L3: Yes
A4: https://4ammedia.zendesk.com/agent/tickets/212102 | B4: 46209 | C4: =IF(B4="", "", TEXT(B4, "ddd")) -> Mon | D4: =IF(E4="Yes",0.05,0) +IF(F4="Yes",0.1,0) +IF(G4="Yes",0.15,0) +IF(H4="Yes",0.15,0) +IF(I4="Yes",0.05,0) +IF(J4="Yes",0.05,0) +IF(K4="Yes",0.15,0) +IF(L4="Yes",0.3,0) -> 1 | E4: Yes | F4: Yes | G4: Yes | H4: Yes | I4: Yes | J4: Yes | K4: Yes | L4: Yes
A5: https://4ammedia.zendesk.com/agent/tickets/212359 | B5: 46209 | C5: =IF(B5="", "", TEXT(B5, "ddd")) -> Mon | D5: =IF(E5="Yes",0.05,0) +IF(F5="Yes",0.1,0) +IF(G5="Yes",0.15,0) +IF(H5="Yes",0.15,0) +IF(I5="Yes",0.05,0) +IF(J5="Yes",0.05,0) +IF(K5="Yes",0.15,0) +IF(L5="Yes",0.3,0) -> 1 | E5: Yes | F5: Yes | G5: Yes | H5: Yes | I5: Yes | J5: Yes | K5: Yes | L5: Yes
A6: https://4ammedia.zendesk.com/agent/tickets/213864 | B6: 46210 | C6: =IF(B6="", "", TEXT(B6, "ddd")) -> Tue | D6: =IF(E6="Yes",0.05,0) +IF(F6="Yes",0.1,0) +IF(G6="Yes",0.15,0) +IF(H6="Yes",0.15,0) +IF(I6="Yes",0.05,0) +IF(J6="Yes",0.05,0) +IF(K6="Yes",0.15,0) +IF(L6="Yes",0.3,0) -> 1 | E6: Yes | F6: Yes | G6: Yes | H6: Yes | I6: Yes | J6: Yes | K6: Yes | L6: Yes
A7: https://4ammedia.zendesk.com/agent/tickets/213999 | B7: 46210 | C7: =IF(B7="", "", TEXT(B7, "ddd")) -> Tue | D7: =IF(E7="Yes",0.05,0) +IF(F7="Yes",0.1,0) +IF(G7="Yes",0.15,0) +IF(H7="Yes",0.15,0) +IF(I7="Yes",0.05,0) +IF(J7="Yes",0.05,0) +IF(K7="Yes",0.15,0) +IF(L7="Yes",0.3,0) -> 1 | E7: Yes | F7: Yes | G7: Yes | H7: Yes | I7: Yes | J7: Yes | K7: Yes | L7: Yes
A8: https://4ammedia.zendesk.com/agent/tickets/214389 | B8: 46210 | C8: =IF(B8="", "", TEXT(B8, "ddd")) -> Tue | D8: =IF(E8="Yes",0.05,0) +IF(F8="Yes",0.1,0) +IF(G8="Yes",0.15,0) +IF(H8="Yes",0.15,0) +IF(I8="Yes",0.05,0) +IF(J8="Yes",0.05,0) +IF(K8="Yes",0.15,0) +IF(L8="Yes",0.3,0) -> 1 | E8: Yes | F8: Yes | G8: Yes | H8: Yes | I8: Yes | J8: Yes | K8: Yes | L8: Yes
A9: https://4ammedia.zendesk.com/agent/tickets/215731 | B9: 46211 | C9: =IF(B9="", "", TEXT(B9, "ddd")) -> Wed | D9: =IF(E9="Yes",0.05,0) +IF(F9="Yes",0.1,0) +IF(G9="Yes",0.15,0) +IF(H9="Yes",0.15,0) +IF(I9="Yes",0.05,0) +IF(J9="Yes",0.05,0) +IF(K9="Yes",0.15,0) +IF(L9="Yes",0.3,0) -> 1 | E9: Yes | F9: Yes | G9: Yes | H9: Yes | I9: Yes | J9: Yes | K9: Yes | L9: Yes
A10: https://4ammedia.zendesk.com/agent/tickets/215937 | B10: 46211 | C10: =IF(B10="", "", TEXT(B10, "ddd")) -> Wed | D10: =IF(E10="Yes",0.05,0) +IF(F10="Yes",0.1,0) +IF(G10="Yes",0.15,0) +IF(H10="Yes",0.15,0) +IF(I10="Yes",0.05,0) +IF(J10="Yes",0.05,0) +IF(K10="Yes",0.15,0) +IF(L10="Yes",0.3,0) -> 1 | E10: Yes | F10: Yes | G10: Yes | H10: Yes | I10: Yes | J10: Yes | K10: Yes | L10: Yes
A11: https://4ammedia.zendesk.com/agent/tickets/215976 | B11: 46211 | C11: =IF(B11="", "", TEXT(B11, "ddd")) -> Wed | D11: =IF(E11="Yes",0.05,0) +IF(F11="Yes",0.1,0) +IF(G11="Yes",0.15,0) +IF(H11="Yes",0.15,0) +IF(I11="Yes",0.05,0) +IF(J11="Yes",0.05,0) +IF(K11="Yes",0.15,0) +IF(L11="Yes",0.3,0) -> 1 | E11: Yes | F11: Yes | G11: Yes | H11: Yes | I11: Yes | J11: Yes | K11: Yes | L11: Yes
A12: https://4ammedia.zendesk.com/agent/tickets/217776 | B12: 46212 | C12: =IF(B12="", "", TEXT(B12, "ddd")) -> Thu | D12: =IF(E12="Yes",0.05,0) +IF(F12="Yes",0.1,0) +IF(G12="Yes",0.15,0) +IF(H12="Yes",0.15,0) +IF(I12="Yes",0.05,0) +IF(J12="Yes",0.05,0) +IF(K12="Yes",0.15,0) +IF(L12="Yes",0.3,0) -> 1 | E12: Yes | F12: Yes | G12: Yes | H12: Yes | I12: Yes | J12: Yes | K12: Yes | L12: Yes
A13: https://4ammedia.zendesk.com/agent/tickets/217908 | B13: 46212 | C13: =IF(B13="", "", TEXT(B13, "ddd")) -> Thu | D13: =IF(E13="Yes",0.05,0) +IF(F13="Yes",0.1,0) +IF(G13="Yes",0.15,0) +IF(H13="Yes",0.15,0) +IF(I13="Yes",0.05,0) +IF(J13="Yes",0.05,0) +IF(K13="Yes",0.15,0) +IF(L13="Yes",0.3,0) -> 1 | E13: Yes | F13: Yes | G13: Yes | H13: Yes | I13: Yes | J13: Yes | K13: Yes | L13: Yes
A14: https://4ammedia.zendesk.com/agent/tickets/218017 | B14: 46212 | C14: =IF(B14="", "", TEXT(B14, "ddd")) -> Thu | D14: =IF(E14="Yes",0.05,0) +IF(F14="Yes",0.1,0) +IF(G14="Yes",0.15,0) +IF(H14="Yes",0.15,0) +IF(I14="Yes",0.05,0) +IF(J14="Yes",0.05,0) +IF(K14="Yes",0.15,0) +IF(L14="Yes",0.3,0) -> 1 | E14: Yes | F14: Yes | G14: Yes | H14: Yes | I14: Yes | J14: Yes | K14: Yes | L14: Yes
... A17: https://4ammedia.zendesk.com/agent/tickets/219749 | B17: 46213 | C17: =IF(B17="", "", TEXT(B17, "ddd")) -> Fri | D17: =IF(E17="Yes",0.05,0) +IF(F17="Yes",0.1,0) +IF(G17="Yes",0.15,0) +IF(H17="Yes",0.15,0) +IF(I17="Yes",0.05,0) +IF(J17="Yes",0.05,0) +IF(K17="Yes",0.15,0) +IF(L17="Yes",0.3,0) -> 1 | E17: Yes | F17: Yes | G17: Yes | H17: Yes | I17: Yes | J17: Yes | K17: Yes | L17: Yes
C18: Final QA Score | D18: =AVERAGE(D3:D17) -> 1 | L18: Final QA Score | M18: =SUM(M3:M17)/75*0.1 -> 0
A19: Week (July 13, - July 19,2026)
A20: Ticket Link | B20: Date | C20: Day | D20: SCORE | E20: Notes and Tagging(internal Note and Sticky Note) 5% | F20: COURTESY & EMPATHY 15% | G20: TONE OF VOICE & ELOQUENCE 20% | H20: CALL CONTROL 15% | I20: VERIFICATION 5% | J20: PROBING 5% | K20: MASTERY OF INFORMATION 15% | L20: RESOLUTION 20% | M20: Average | N20: NOTES
A21: https://4ammedia.zendesk.com/agent/tickets/224286 | B21: 46216 | C21: =IF(B21="", "", TEXT(B21, "ddd")) -> Mon | D21: =IF(E21="Yes",0.05,0) +IF(F21="Yes",0.1,0) +IF(G21="Yes",0.15,0) +IF(H21="Yes",0.15,0) +IF(I21="Yes",0.05,0) +IF(J21="Yes",0.05,0) +IF(K21="Yes",0.15,0) +IF(L21="Yes",0.3,0) -> 1 | E21: Yes | F21: Yes | G21: Yes | H21: Yes | I21: Yes | J21: Yes | K21: Yes | L21: Yes
A22: https://4ammedia.zendesk.com/agent/tickets/224667 | B22: 46216 | C22: =IF(B22="", "", TEXT(B22, "ddd")) -> Mon | D22: =IF(E22="Yes",0.05,0) +IF(F22="Yes",0.1,0) +IF(G22="Yes",0.15,0) +IF(H22="Yes",0.15,0) +IF(I22="Yes",0.05,0) +IF(J22="Yes",0.05,0) +IF(K22="Yes",0.15,0) +IF(L22="Yes",0.3,0) -> 1 | E22: Yes | F22: Yes | G22: Yes | H22: Yes | I22: Yes | J22: Yes | K22: Yes | L22: Yes
A23: https://4ammedia.zendesk.com/agent/tickets/224692 | B23: 46216 | C23: =IF(B23="", "", TEXT(B23, "ddd")) -> Mon | D23: =IF(E23="Yes",0.05,0) +IF(F23="Yes",0.1,0) +IF(G23="Yes",0.15,0) +IF(H23="Yes",0.15,0) +IF(I23="Yes",0.05,0) +IF(J23="Yes",0.05,0) +IF(K23="Yes",0.15,0) +IF(L23="Yes",0.3,0) -> 1 | E23: Yes | F23: Yes | G23: Yes | H23: Yes | I23: Yes | J23: Yes | K23: Yes | L23: Yes
A24: https://4ammedia.zendesk.com/agent/tickets/227009 | B24: 46217 | C24: =IF(B24="", "", TEXT(B24, "ddd")) -> Tue | D24: =IF(E24="Yes",0.05,0) +IF(F24="Yes",0.1,0) +IF(G24="Yes",0.15,0) +IF(H24="Yes",0.15,0) +IF(I24="Yes",0.05,0) +IF(J24="Yes",0.05,0) +IF(K24="Yes",0.15,0) +IF(L24="Yes",0.3,0) -> 1 | E24: Yes | F24: Yes | G24: Yes | H24: Yes | I24: Yes | J24: Yes | K24: Yes | L24: Yes
A25: https://4ammedia.zendesk.com/agent/tickets/227026 | B25: 46217 | C25: =IF(B25="", "", TEXT(B25, "ddd")) -> Tue | D25: =IF(E25="Yes",0.05,0) +IF(F25="Yes",0.1,0) +IF(G25="Yes",0.15,0) +IF(H25="Yes",0.15,0) +IF(I25="Yes",0.05,0) +IF(J25="Yes",0.05,0) +IF(K25="Yes",0.15,0) +IF(L25="Yes",0.3,0) -> 1 | E25: Yes | F25: Yes | G25: Yes | H25: Yes | I25: Yes | J25: Yes | K25: Yes | L25: Yes
A26: https://4ammedia.zendesk.com/agent/tickets/227041 | B26: 46217 | C26: =IF(B26="", "", TEXT(B26, "ddd")) -> Tue | D26: =IF(E26="Yes",0.05,0) +IF(F26="Yes",0.1,0) +IF(G26="Yes",0.15,0) +IF(H26="Yes",0.15,0) +IF(I26="Yes",0.05,0) +IF(J26="Yes",0.05,0) +IF(K26="Yes",0.15,0) +IF(L26="Yes",0.3,0) -> 1 | E26: Yes | F26: Yes | G26: Yes | H26: Yes | I26: Yes | J26: Yes | K26: Yes | L26: Yes
A27: https://4ammedia.zendesk.com/agent/tickets/228642 | B27: 46218 | C27: =IF(B27="", "", TEXT(B27, "ddd")) -> Wed | D27: =IF(E27="Yes",0.05,0) +IF(F27="Yes",0.1,0) +IF(G27="Yes",0.15,0) +IF(H27="Yes",0.15,0) +IF(I27="Yes",0.05,0) +IF(J27="Yes",0.05,0) +IF(K27="Yes",0.15,0) +IF(L27="Yes",0.3,0) -> 1 | E27: Yes | F27: Yes | G27: Yes | H27: Yes | I27: Yes | J27: Yes | K27: Yes | L27: Yes
A28: https://4ammedia.zendesk.com/agent/tickets/228813 | B28: 46218 | C28: =IF(B28="", "", TEXT(B28, "ddd")) -> Wed | D28: =IF(E28="Yes",0.05,0) +IF(F28="Yes",0.1,0) +IF(G28="Yes",0.15,0) +IF(H28="Yes",0.15,0) +IF(I28="Yes",0.05,0) +IF(J28="Yes",0.05,0) +IF(K28="Yes",0.15,0) +IF(L28="Yes",0.3,0) -> 1 | E28: Yes | F28: Yes | G28: Yes | H28: Yes | I28: Yes | J28: Yes | K28: Yes | L28: Yes
A29: https://4ammedia.zendesk.com/agent/tickets/228944 | B29: 46218 | C29: =IF(B29="", "", TEXT(B29, "ddd")) -> Wed | D29: =IF(E29="Yes",0.05,0) +IF(F29="Yes",0.1,0) +IF(G29="Yes",0.15,0) +IF(H29="Yes",0.15,0) +IF(I29="Yes",0.05,0) +IF(J29="Yes",0.05,0) +IF(K29="Yes",0.15,0) +IF(L29="Yes",0.3,0) -> 1 | E29: Yes | F29: Yes | G29: Yes | H29: Yes | I29: Yes | J29: Yes | K29: Yes | L29: Yes
A30: https://4ammedia.zendesk.com/agent/tickets/230672 | B30: 46219 | C30: =IF(B30="", "", TEXT(B30, "ddd")) -> Thu | D30: =IF(E30="Yes",0.05,0) +IF(F30="Yes",0.1,0) +IF(G30="Yes",0.15,0) +IF(H30="Yes",0.15,0) +IF(I30="Yes",0.05,0) +IF(J30="Yes",0.05,0) +IF(K30="Yes",0.15,0) +IF(L30="Yes",0.3,0) -> 1 | E30: Yes | F30: Yes | G30: Yes | H30: Yes | I30: Yes | J30: Yes | K30: Yes | L30: Yes
A31: https://4ammedia.zendesk.com/agent/tickets/230808 | B31: 46219 | C31: =IF(B31="", "", TEXT(B31, "ddd")) -> Thu | D31: =IF(E31="Yes",0.05,0) +IF(F31="Yes",0.1,0) +IF(G31="Yes",0.15,0) +IF(H31="Yes",0.15,0) +IF(I31="Yes",0.05,0) +IF(J31="Yes",0.05,0) +IF(K31="Yes",0.15,0) +IF(L31="Yes",0.3,0) -> 1 | E31: Yes | F31: Yes | G31: Yes | H31: Yes | I31: Yes | J31: Yes | K31: Yes | L31: Yes
A32: https://4ammedia.zendesk.com/agent/tickets/230885 | B32: 46219 | C32: =IF(B32="", "", TEXT(B32, "ddd")) -> Thu | D32: =IF(E32="Yes",0.05,0) +IF(F32="Yes",0.1,0) +IF(G32="Yes",0.15,0) +IF(H32="Yes",0.15,0) +IF(I32="Yes",0.05,0) +IF(J32="Yes",0.05,0) +IF(K32="Yes",0.15,0) +IF(L32="Yes",0.3,0) -> 1 | E32: Yes | F32: Yes | G32: Yes | H32: Yes | I32: Yes | J32: Yes | K32: Yes | L32: Yes
... A35: https://4ammedia.zendesk.com/agent/tickets/232550 | B35: 46220 | C35: =IF(B35="", "", TEXT(B35, "ddd")) -> Fri | D35: =IF(E35="Yes",0.05,0) +IF(F35="Yes",0.1,0) +IF(G35="Yes",0.15,0) +IF(H35="Yes",0.15,0) +IF(I35="Yes",0.05,0) +IF(J35="Yes",0.05,0) +IF(K35="Yes",0.15,0) +IF(L35="Yes",0.3,0) -> 1 | E35: Yes | F35: Yes | G35: Yes | H35: Yes | I35: Yes | J35: Yes | K35: Yes | L35: Yes
C36: Final QA Score | D36: =AVERAGE(D21:D35) -> 1 | L36: Final QA Score | M36: =SUM(M21:M35)/75*0.1 -> 0
A37: Week (July 20, - July 26,2026)
A38: Ticket Link | B38: Date | C38: Day | D38: SCORE | E38: Notes and Tagging(internal Note and Sticky Note) 5% | F38: COURTESY & EMPATHY 15% | G38: TONE OF VOICE & ELOQUENCE 20% | H38: CALL CONTROL 15% | I38: VERIFICATION 5% | J38: PROBING 5% | K38: MASTERY OF INFORMATION 15% | L38: RESOLUTION 20% | M38: Average | N38: NOTES
A39: https://4ammedia.zendesk.com/agent/tickets/237008 | B39: 46223 | C39: =IF(B39="", "", TEXT(B39, "ddd")) -> Mon | D39: =IF(E39="Yes",0.05,0) +IF(F39="Yes",0.1,0) +IF(G39="Yes",0.15,0) +IF(H39="Yes",0.15,0) +IF(I39="Yes",0.05,0) +IF(J39="Yes",0.05,0) +IF(K39="Yes",0.15,0) +IF(L39="Yes",0.3,0) -> 1 | E39: Yes | F39: Yes | G39: Yes | H39: Yes | I39: Yes | J39: Yes | K39: Yes | L39: Yes
A40: https://4ammedia.zendesk.com/agent/tickets/237202 | B40: 46223 | C40: =IF(B40="", "", TEXT(B40, "ddd")) -> Mon | D40: =IF(E40="Yes",0.05,0) +IF(F40="Yes",0.1,0) +IF(G40="Yes",0.15,0) +IF(H40="Yes",0.15,0) +IF(I40="Yes",0.05,0) +IF(J40="Yes",0.05,0) +IF(K40="Yes",0.15,0) +IF(L40="Yes",0.3,0) -> 1 | E40: Yes | F40: Yes | G40: Yes | H40: Yes | I40: Yes | J40: Yes | K40: Yes | L40: Yes
A41: https://4ammedia.zendesk.com/agent/tickets/237280 | B41: 46223 | C41: =IF(B41="", "", TEXT(B41, "ddd")) -> Mon | D41: =IF(E41="Yes",0.05,0) +IF(F41="Yes",0.1,0) +IF(G41="Yes",0.15,0) +IF(H41="Yes",0.15,0) +IF(I41="Yes",0.05,0) +IF(J41="Yes",0.05,0) +IF(K41="Yes",0.15,0) +IF(L41="Yes",0.3,0) -> 1 | E41: Yes | F41: Yes | G41: Yes | H41: Yes | I41: Yes | J41: Yes | K41: Yes | L41: Yes
A42: https://4ammedia.zendesk.com/agent/tickets/239606 | B42: 46224 | C42: =IF(B42="", "", TEXT(B42, "ddd")) -> Tue | D42: =IF(E42="Yes",0.05,0) +IF(F42="Yes",0.1,0) +IF(G42="Yes",0.15,0) +IF(H42="Yes",0.15,0) +IF(I42="Yes",0.05,0) +IF(J42="Yes",0.05,0) +IF(K42="Yes",0.15,0) +IF(L42="Yes",0.3,0) -> 1 | E42: Yes | F42: Yes | G42: Yes | H42: Yes | I42: Yes | J42: Yes | K42: Yes | L42: Yes
A43: https://4ammedia.zendesk.com/agent/tickets/239679 | B43: 46224 | C43: =IF(B43="", "", TEXT(B43, "ddd")) -> Tue | D43: =IF(E43="Yes",0.05,0) +IF(F43="Yes",0.1,0) +IF(G43="Yes",0.15,0) +IF(H43="Yes",0.15,0) +IF(I43="Yes",0.05,0) +IF(J43="Yes",0.05,0) +IF(K43="Yes",0.15,0) +IF(L43="Yes",0.3,0) -> 1 | E43: Yes | F43: Yes | G43: Yes | H43: Yes | I43: Yes | J43: Yes | K43: Yes | L43: Yes
A44: https://4ammedia.zendesk.com/agent/tickets/239705 | B44: 46224 | C44: =IF(B44="", "", TEXT(B44, "ddd")) -> Tue | D44: =IF(E44="Yes",0.05,0) +IF(F44="Yes",0.1,0) +IF(G44="Yes",0.15,0) +IF(H44="Yes",0.15,0) +IF(I44="Yes",0.05,0) +IF(J44="Yes",0.05,0) +IF(K44="Yes",0.15,0) +IF(L44="Yes",0.3,0) -> 1 | E44: Yes | F44: Yes | G44: Yes | H44: Yes | I44: Yes | J44: Yes | K44: Yes | L44: Yes
...

Sheet Godwin
A1: Week (July 13, - July 19,2026)
A2: Ticket Link | B2: Date | C2: Day | D2: SCORE | E2: Notes and Tagging(internal Note and Sticky Note) 5% | F2: COURTESY & EMPATHY 15% | G2: TONE OF VOICE & ELOQUENCE 20% | H2: CALL CONTROL 15% | I2: VERIFICATION 5% | J2: PROBING 5% | K2: MASTERY OF INFORMATION 15% | L2: RESOLUTION 20% | M2: Average | N2: NOTES
A3: https://4ammedia.zendesk.com/agent/tickets/223595 | B3: 46216 | C3: =IF(B3="", "", TEXT(B3, "ddd")) -> Mon | D3: =IF(E3="Yes",0.05,0) +IF(F3="Yes",0.1,0) +IF(G3="Yes",0.15,0) +IF(H3="Yes",0.15,0) +IF(I3="Yes",0.05,0) +IF(J3="Yes",0.05,0) +IF(K3="Yes",0.15,0) +IF(L3="Yes",0.3,0) -> 1 | E3: Yes | F3: Yes | G3: Yes | H3: Yes | I3: Yes | J3: Yes | K3: Yes | L3: Yes
A4: https://4ammedia.zendesk.com/agent/tickets/224343 | B4: 46216 | C4: =IF(B4="", "", TEXT(B4, "ddd")) -> Mon | D4: =IF(E4="Yes",0.05,0) +IF(F4="Yes",0.1,0) +IF(G4="Yes",0.15,0) +IF(H4="Yes",0.15,0) +IF(I4="Yes",0.05,0) +IF(J4="Yes",0.05,0) +IF(K4="Yes",0.15,0) +IF(L4="Yes",0.3,0) -> 1 | E4: Yes | F4: Yes | G4: Yes | H4: Yes | I4: Yes | J4: Yes | K4: Yes | L4: Yes
A5: https://4ammedia.zendesk.com/agent/tickets/224486 | B5: 46216 | C5: =IF(B5="", "", TEXT(B5, "ddd")) -> Mon | D5: =IF(E5="Yes",0.05,0) +IF(F5="Yes",0.1,0) +IF(G5="Yes",0.15,0) +IF(H5="Yes",0.15,0) +IF(I5="Yes",0.05,0) +IF(J5="Yes",0.05,0) +IF(K5="Yes",0.15,0) +IF(L5="Yes",0.3,0) -> 1 | E5: Yes | F5: Yes | G5: Yes | H5: Yes | I5: Yes | J5: Yes | K5: Yes | L5: Yes
A6: https://4ammedia.zendesk.com/agent/tickets/226136 | B6: 46217 | C6: =IF(B6="", "", TEXT(B6, "ddd")) -> Tue | D6: =IF(E6="Yes",0.05,0) +IF(F6="Yes",0.1,0) +IF(G6="Yes",0.15,0) +IF(H6="Yes",0.15,0) +IF(I6="Yes",0.05,0) +IF(J6="Yes",0.05,0) +IF(K6="Yes",0.15,0) +IF(L6="Yes",0.3,0) -> 1 | E6: Yes | F6: Yes | G6: Yes | H6: Yes | I6: Yes | J6: Yes | K6: Yes | L6: Yes
A7: https://4ammedia.zendesk.com/agent/tickets/226291 | B7: 46217 | C7: =IF(B7="", "", TEXT(B7, "ddd")) -> Tue | D7: =IF(E7="Yes",0.05,0) +IF(F7="Yes",0.1,0) +IF(G7="Yes",0.15,0) +IF(H7="Yes",0.15,0) +IF(I7="Yes",0.05,0) +IF(J7="Yes",0.05,0) +IF(K7="Yes",0.15,0) +IF(L7="Yes",0.3,0) -> 1 | E7: Yes | F7: Yes | G7: Yes | H7: Yes | I7: Yes | J7: Yes | K7: Yes | L7: Yes
A8: https://4ammedia.zendesk.com/agent/tickets/226607 | B8: 46217 | C8: =IF(B8="", "", TEXT(B8, "ddd")) -> Tue | D8: =IF(E8="Yes",0.05,0) +IF(F8="Yes",0.1,0) +IF(G8="Yes",0.15,0) +IF(H8="Yes",0.15,0) +IF(I8="Yes",0.05,0) +IF(J8="Yes",0.05,0) +IF(K8="Yes",0.15,0) +IF(L8="Yes",0.3,0) -> 1 | E8: Yes | F8: Yes | G8: Yes | H8: Yes | I8: Yes | J8: Yes | K8: Yes | L8: Yes
A9: https://4ammedia.zendesk.com/agent/tickets/228198 | B9: 46218 | C9: =IF(B9="", "", TEXT(B9, "ddd")) -> Wed | D9: =IF(E9="Yes",0.05,0) +IF(F9="Yes",0.1,0) +IF(G9="Yes",0.15,0) +IF(H9="Yes",0.15,0) +IF(I9="Yes",0.05,0) +IF(J9="Yes",0.05,0) +IF(K9="Yes",0.15,0) +IF(L9="Yes",0.3,0) -> 1 | E9: Yes | F9: Yes | G9: Yes | H9: Yes | I9: Yes | J9: Yes | K9: Yes | L9: Yes
A10: https://4ammedia.zendesk.com/agent/tickets/228419 | B10: 46218 | C10: =IF(B10="", "", TEXT(B10, "ddd")) -> Wed | D10: =IF(E10="Yes",0.05,0) +IF(F10="Yes",0.1,0) +IF(G10="Yes",0.15,0) +IF(H10="Yes",0.15,0) +IF(I10="Yes",0.05,0) +IF(J10="Yes",0.05,0) +IF(K10="Yes",0.15,0) +IF(L10="Yes",0.3,0) -> 1 | E10: Yes | F10: Yes | G10: Yes | H10: Yes | I10: Yes | J10: Yes | K10: Yes | L10: Yes
A11: https://4ammedia.zendesk.com/agent/tickets/228441 | B11: 46218 | C11: =IF(B11="", "", TEXT(B11, "ddd")) -> Wed | D11: =IF(E11="Yes",0.05,0) +IF(F11="Yes",0.1,0) +IF(G11="Yes",0.15,0) +IF(H11="Yes",0.15,0) +IF(I11="Yes",0.05,0) +IF(J11="Yes",0.05,0) +IF(K11="Yes",0.15,0) +IF(L11="Yes",0.3,0) -> 1 | E11: Yes | F11: Yes | G11: Yes | H11: Yes | I11: Yes | J11: Yes | K11: Yes | L11: Yes
A12: https://4ammedia.zendesk.com/agent/tickets/229821 | B12: 46219 | C12: =IF(B12="", "", TEXT(B12, "ddd")) -> Thu | D12: =IF(E12="Yes",0.05,0) +IF(F12="Yes",0.1,0) +IF(G12="Yes",0.15,0) +IF(H12="Yes",0.15,0) +IF(I12="Yes",0.05,0) +IF(J12="Yes",0.05,0) +IF(K12="Yes",0.15,0) +IF(L12="Yes",0.3,0) -> 1 | E12: Yes | F12: Yes | G12: Yes | H12: Yes | I12: Yes | J12: Yes | K12: Yes | L12: Yes
A13: https://4ammedia.zendesk.com/agent/tickets/230130 | B13: 46219 | C13: =IF(B13="", "", TEXT(B13, "ddd")) -> Thu | D13: =IF(E13="Yes",0.05,0) +IF(F13="Yes",0.1,0) +IF(G13="Yes",0.15,0) +IF(H13="Yes",0.15,0) +IF(I13="Yes",0.05,0) +IF(J13="Yes",0.05,0) +IF(K13="Yes",0.15,0) +IF(L13="Yes",0.3,0) -> 1 | E13: Yes | F13: Yes | G13: Yes | H13: Yes | I13: Yes | J13: Yes | K13: Yes | L13: Yes
A14: https://4ammedia.zendesk.com/agent/tickets/230168 | B14: 46219 | C14: =IF(B14="", "", TEXT(B14, "ddd")) -> Thu | D14: =IF(E14="Yes",0.05,0) +IF(F14="Yes",0.1,0) +IF(G14="Yes",0.15,0) +IF(H14="Yes",0.15,0) +IF(I14="Yes",0.05,0) +IF(J14="Yes",0.05,0) +IF(K14="Yes",0.15,0) +IF(L14="Yes",0.3,0) -> 1 | E14: Yes | F14: Yes | G14: Yes | H14: Yes | I14: Yes | J14: Yes | K14: Yes | L14: Yes
... A17: https://4ammedia.zendesk.com/agent/tickets/232457 | B17: 46220 | C17: =IF(B17="", "", TEXT(B17, "ddd")) -> Fri | D17: =IF(E17="Yes",0.05,0) +IF(F17="Yes",0.1,0) +IF(G17="Yes",0.15,0) +IF(H17="Yes",0.15,0) +IF(I17="Yes",0.05,0) +IF(J17="Yes",0.05,0) +IF(K17="Yes",0.15,0) +IF(L17="Yes",0.3,0) -> 1 | E17: Yes | F17: Yes | G17: Yes | H17: Yes | I17: Yes | J17: Yes | K17: Yes | L17: Yes
C18: Final QA Score | D18: =AVERAGE(D3:D17) -> 1 | L18: Final QA Score | M18: =SUM(M3:M17)/75*0.1 -> 0
A19: Week (July 20, - July 26,2026)
A20: Ticket Link | B20: Date | C20: Day | D20: SCORE | E20: Notes and Tagging(internal Note and Sticky Note) 5% | F20: COURTESY & EMPATHY 15% | G20: TONE OF VOICE & ELOQUENCE 20% | H20: CALL CONTROL 15% | I20: VERIFICATION 5% | J20: PROBING 5% | K20: MASTERY OF INFORMATION 15% | L20: RESOLUTION 20% | M20: Average | N20: NOTES
A21: https://4ammedia.zendesk.com/agent/tickets/236232 | B21: 46223 | C21: =IF(B21="", "", TEXT(B21, "ddd")) -> Mon | D21: =IF(E21="Yes",0.05,0) +IF(F21="Yes",0.1,0) +IF(G21="Yes",0.15,0) +IF(H21="Yes",0.15,0) +IF(I21="Yes",0.05,0) +IF(J21="Yes",0.05,0) +IF(K21="Yes",0.15,0) +IF(L21="Yes",0.3,0) -> 1 | E21: Yes | F21: Yes | G21: Yes | H21: Yes | I21: Yes | J21: Yes | K21: Yes | L21: Yes
A22: https://4ammedia.zendesk.com/agent/tickets/236317 | B22: 46223 | C22: =IF(B22="", "", TEXT(B22, "ddd")) -> Mon | D22: =IF(E22="Yes",0.05,0) +IF(F22="Yes",0.1,0) +IF(G22="Yes",0.15,0) +IF(H22="Yes",0.15,0) +IF(I22="Yes",0.05,0) +IF(J22="Yes",0.05,0) +IF(K22="Yes",0.15,0) +IF(L22="Yes",0.3,0) -> 1 | E22: Yes | F22: Yes | G22: Yes | H22: Yes | I22: Yes | J22: Yes | K22: Yes | L22: Yes
A23: https://4ammedia.zendesk.com/agent/tickets/236484 | B23: 46223 | C23: =IF(B23="", "", TEXT(B23, "ddd")) -> Mon | D23: =IF(E23="Yes",0.05,0) +IF(F23="Yes",0.1,0) +IF(G23="Yes",0.15,0) +IF(H23="Yes",0.15,0) +IF(I23="Yes",0.05,0) +IF(J23="Yes",0.05,0) +IF(K23="Yes",0.15,0) +IF(L23="Yes",0.3,0) -> 1 | E23: Yes | F23: Yes | G23: Yes | H23: Yes | I23: Yes | J23: Yes | K23: Yes | L23: Yes
A24: https://4ammedia.zendesk.com/agent/tickets/238404 | B24: 46224 | C24: =IF(B24="", "", TEXT(B24, "ddd")) -> Tue | D24: =IF(E24="Yes",0.05,0) +IF(F24="Yes",0.1,0) +IF(G24="Yes",0.15,0) +IF(H24="Yes",0.15,0) +IF(I24="Yes",0.05,0) +IF(J24="Yes",0.05,0) +IF(K24="Yes",0.15,0) +IF(L24="Yes",0.3,0) -> 1 | E24: Yes | F24: Yes | G24: Yes | H24: Yes | I24: Yes | J24: Yes | K24: Yes | L24: Yes
A25: https://4ammedia.zendesk.com/agent/tickets/238524 | B25: 46224 | C25: =IF(B25="", "", TEXT(B25, "ddd")) -> Tue | D25: =IF(E25="Yes",0.05,0) +IF(F25="Yes",0.1,0) +IF(G25="Yes",0.15,0) +IF(H25="Yes",0.15,0) +IF(I25="Yes",0.05,0) +IF(J25="Yes",0.05,0) +IF(K25="Yes",0.15,0) +IF(L25="Yes",0.3,0) -> 1 | E25: Yes | F25: Yes | G25: Yes | H25: Yes | I25: Yes | J25: Yes | K25: Yes | L25: Yes
A26: https://4ammedia.zendesk.com/agent/tickets/238723 | B26: 46224 | C26: =IF(B26="", "", TEXT(B26, "ddd")) -> Tue | D26: =IF(E26="Yes",0.05,0) +IF(F26="Yes",0.1,0) +IF(G26="Yes",0.15,0) +IF(H26="Yes",0.15,0) +IF(I26="Yes",0.05,0) +IF(J26="Yes",0.05,0) +IF(K26="Yes",0.15,0) +IF(L26="Yes",0.3,0) -> 1 | E26: Yes | F26: Yes | G26: Yes | H26: Yes | I26: Yes | J26: Yes | K26: Yes | L26: Yes
A27: https://4ammedia.zendesk.com/agent/tickets/241119 | B27: 46225 | C27: =IF(B27="", "", TEXT(B27, "ddd")) -> Wed | D27: =IF(E27="Yes",0.05,0) +IF(F27="Yes",0.1,0) +IF(G27="Yes",0.15,0) +IF(H27="Yes",0.15,0) +IF(I27="Yes",0.05,0) +IF(J27="Yes",0.05,0) +IF(K27="Yes",0.15,0) +IF(L27="Yes",0.3,0) -> 1 | E27: Yes | F27: Yes | G27: Yes | H27: Yes | I27: Yes | J27: Yes | K27: Yes | L27: Yes
A28: https://4ammedia.zendesk.com/agent/tickets/241250 | B28: 46225 | C28: =IF(B28="", "", TEXT(B28, "ddd")) -> Wed | D28: =IF(E28="Yes",0.05,0) +IF(F28="Yes",0.1,0) +IF(G28="Yes",0.15,0) +IF(H28="Yes",0.15,0) +IF(I28="Yes",0.05,0) +IF(J28="Yes",0.05,0) +IF(K28="Yes",0.15,0) +IF(L28="Yes",0.3,0) -> 1 | E28: Yes | F28: Yes | G28: Yes | H28: Yes | I28: Yes | J28: Yes | K28: Yes | L28: Yes
A29: https://4ammedia.zendesk.com/agent/tickets/241481 | B29: 46225 | C29: =IF(B29="", "", TEXT(B29, "ddd")) -> Wed | D29: =IF(E29="Yes",0.05,0) +IF(F29="Yes",0.1,0) +IF(G29="Yes",0.15,0) +IF(H29="Yes",0.15,0) +IF(I29="Yes",0.05,0) +IF(J29="Yes",0.05,0) +IF(K29="Yes",0.15,0) +IF(L29="Yes",0.3,0) -> 1 | E29: Yes | F29: Yes | G29: Yes | H29: Yes | I29: Yes | J29: Yes | K29: Yes | L29: Yes
A30: https://4ammedia.zendesk.com/agent/tickets/243006 | B30: 46226 | C30: =IF(B30="", "", TEXT(B30, "ddd")) -> Thu | D30: =IF(E30="Yes",0.05,0) +IF(F30="Yes",0.1,0) +IF(G30="Yes",0.15,0) +IF(H30="Yes",0.15,0) +IF(I30="Yes",0.05,0) +IF(J30="Yes",0.05,0) +IF(K30="Yes",0.15,0) +IF(L30="Yes",0.3,0) -> 1 | E30: Yes | F30: Yes | G30: Yes | H30: Yes | I30: Yes | J30: Yes | K30: Yes | L30: Yes
A31: https://4ammedia.zendesk.com/agent/tickets/243358 | B31: 46226 | C31: =IF(B31="", "", TEXT(B31, "ddd")) -> Thu | D31: =IF(E31="Yes",0.05,0) +IF(F31="Yes",0.1,0) +IF(G31="Yes",0.15,0) +IF(H31="Yes",0.15,0) +IF(I31="Yes",0.05,0) +IF(J31="Yes",0.05,0) +IF(K31="Yes",0.15,0) +IF(L31="Yes",0.3,0) -> 1 | E31: Yes | F31: Yes | G31: Yes | H31: Yes | I31: Yes | J31: Yes | K31: Yes | L31: Yes
A32: https://4ammedia.zendesk.com/agent/tickets/243437 | B32: 46226 | C32: =IF(B32="", "", TEXT(B32, "ddd")) -> Thu | D32: =IF(E32="Yes",0.05,0) +IF(F32="Yes",0.1,0) +IF(G32="Yes",0.15,0) +IF(H32="Yes",0.15,0) +IF(I32="Yes",0.05,0) +IF(J32="Yes",0.05,0) +IF(K32="Yes",0.15,0) +IF(L32="Yes",0.3,0) -> 1 | E32: Yes | F32: Yes | G32: Yes | H32: Yes | I32: Yes | J32: Yes | K32: Yes | L32: Yes
... A35: https://4ammedia.zendesk.com/agent/tickets/245726 | B35: 46227 | C35: =IF(B35="", "", TEXT(B35, "ddd")) -> Fri | D35: =IF(E35="Yes",0.05,0) +IF(F35="Yes",0.1,0) +IF(G35="Yes",0.15,0) +IF(H35="Yes",0.15,0) +IF(I35="Yes",0.05,0) +IF(J35="Yes",0.05,0) +IF(K35="Yes",0.15,0) +IF(L35="Yes",0.3,0) -> 1 | E35: Yes | F35: Yes | G35: Yes | H35: Yes | I35: Yes | J35: Yes | K35: Yes | L35: Yes
C36: Final QA Score | D36: =AVERAGE(D21:D35) -> 1 | L36: Final QA Score | M36: =SUM(M21:M35)/75*0.1 -> 0
A37: Week (July 27, - Aug 2,2026)
A38: Ticket Link | B38: Date | C38: Day | D38: SCORE | E38: Notes and Tagging(internal Note and Sticky Note) 5% | F38: COURTESY & EMPATHY 15% | G38: TONE OF VOICE & ELOQUENCE 20% | H38: CALL CONTROL 15% | I38: VERIFICATION 5% | J38: PROBING 5% | K38: MASTERY OF INFORMATION 15% | L38: RESOLUTION 20% | M38: Average | N38: NOTES
A39: https://4ammedia.zendesk.com/agent/tickets/247831 | B39: 46230 | C39: =IF(B39="", "", TEXT(B39, "ddd")) -> Mon | D39: =IF(E39="Yes",0.05,0) +IF(F39="Yes",0.1,0) +IF(G39="Yes",0.15,0) +IF(H39="Yes",0.15,0) +IF(I39="Yes",0.05,0) +IF(J39="Yes",0.05,0) +IF(K39="Yes",0.15,0) +IF(L39="Yes",0.3,0) -> 1 | E39: Yes | F39: Yes | G39: Yes | H39: Yes | I39: Yes | J39: Yes | K39: Yes | L39: Yes
A40: https://4ammedia.zendesk.com/agent/tickets/249356 | B40: 46230 | C40: =IF(B40="", "", TEXT(B40, "ddd")) -> Mon | D40: =IF(E40="Yes",0.05,0) +IF(F40="Yes",0.1,0) +IF(G40="Yes",0.15,0) +IF(H40="Yes",0.15,0) +IF(I40="Yes",0.05,0) +IF(J40="Yes",0.05,0) +IF(K40="Yes",0.15,0) +IF(L40="Yes",0.3,0) -> 1 | E40: Yes | F40: Yes | G40: Yes | H40: Yes | I40: Yes | J40: Yes | K40: Yes | L40: Yes
A41: https://4ammedia.zendesk.com/agent/tickets/249531 | B41: 46230 | C41: =IF(B41="", "", TEXT(B41, "ddd")) -> Mon | D41: =IF(E41="Yes",0.05,0) +IF(F41="Yes",0.1,0) +IF(G41="Yes",0.15,0) +IF(H41="Yes",0.15,0) +IF(I41="Yes",0.05,0) +IF(J41="Yes",0.05,0) +IF(K41="Yes",0.15,0) +IF(L41="Yes",0.3,0) -> 1 | E41: Yes | F41: Yes | G41: Yes | H41: Yes | I41: Yes | J41: Yes | K41: Yes | L41: Yes
A42: https://4ammedia.zendesk.com/agent/tickets/251980 | B42: 46231 | C42: =IF(B42="", "", TEXT(B42, "ddd")) -> Tue | D42: =IF(E42="Yes",0.05,0) +IF(F42="Yes",0.1,0) +IF(G42="Yes",0.15,0) +IF(H42="Yes",0.15,0) +IF(I42="Yes",0.05,0) +IF(J42="Yes",0.05,0) +IF(K42="Yes",0.15,0) +IF(L42="Yes",0.3,0) -> 1 | E42: Yes | F42: Yes | G42: Yes | H42: Yes | I42: Yes | J42: Yes | K42: Yes | L42: Yes
A43: https://4ammedia.zendesk.com/agent/tickets/252411 | B43: 46231 | C43: =IF(B43="", "", TEXT(B43, "ddd")) -> Tue | D43: =IF(E43="Yes",0.05,0) +IF(F43="Yes",0.1,0) +IF(G43="Yes",0.15,0) +IF(H43="Yes",0.15,0) +IF(I43="Yes",0.05,0) +IF(J43="Yes",0.05,0) +IF(K43="Yes",0.15,0) +IF(L43="Yes",0.3,0) -> 1 | E43: Yes | F43: Yes | G43: Yes | H43: Yes | I43: Yes | J43: Yes | K43: Yes | L43: Yes
A44: https://4ammedia.zendesk.com/agent/tickets/252497 | B44: 46231 | C44: =IF(B44="", "", TEXT(B44, "ddd")) -> Tue | D44: =IF(E44="Yes",0.05,0) +IF(F44="Yes",0.1,0) +IF(G44="Yes",0.15,0) +IF(H44="Yes",0.15,0) +IF(I44="Yes",0.05,0) +IF(J44="Yes",0.05,0) +IF(K44="Yes",0.15,0) +IF(L44="Yes",0.3,0) -> 1 | E44: Yes | F44: Yes | G44: Yes | H44: Yes | I44: Yes | J44: Yes | K44: Yes | L44: Yes
...

Sheet Candy
A1: Week (July 13, - July 19,2026)
A2: Ticket Link | B2: Date | C2: Day | D2: SCORE | E2: Notes and Tagging(internal Note and Sticky Note) 5% | F2: COURTESY & EMPATHY 15% | G2: TONE OF VOICE & ELOQUENCE 20% | H2: CALL CONTROL 15% | I2: VERIFICATION 5% | J2: PROBING 5% | K2: MASTERY OF INFORMATION 15% | L2: RESOLUTION 20% | M2: Average | N2: NOTES
A3: https://4ammedia.zendesk.com/agent/tickets/224171 | B3: 46216 | C3: =IF(B3="", "", TEXT(B3, "ddd")) -> Mon | D3: =IF(E3="Yes",0.05,0) +IF(F3="Yes",0.1,0) +IF(G3="Yes",0.15,0) +IF(H3="Yes",0.15,0) +IF(I3="Yes",0.05,0) +IF(J3="Yes",0.05,0) +IF(K3="Yes",0.15,0) +IF(L3="Yes",0.3,0) -> 1 | E3: Yes | F3: Yes | G3: Yes | H3: Yes | I3: Yes | J3: Yes | K3: Yes | L3: Yes
A4: https://4ammedia.zendesk.com/agent/tickets/224395 | B4: 46216 | C4: =IF(B4="", "", TEXT(B4, "ddd")) -> Mon | D4: =IF(E4="Yes",0.05,0) +IF(F4="Yes",0.1,0) +IF(G4="Yes",0.15,0) +IF(H4="Yes",0.15,0) +IF(I4="Yes",0.05,0) +IF(J4="Yes",0.05,0) +IF(K4="Yes",0.15,0) +IF(L4="Yes",0.3,0) -> 1 | E4: Yes | F4: Yes | G4: Yes | H4: Yes | I4: Yes | J4: Yes | K4: Yes | L4: Yes
A5: https://4ammedia.zendesk.com/agent/tickets/224688 | B5: 46216 | C5: =IF(B5="", "", TEXT(B5, "ddd")) -> Mon | D5: =IF(E5="Yes",0.05,0) +IF(F5="Yes",0.1,0) +IF(G5="Yes",0.15,0) +IF(H5="Yes",0.15,0) +IF(I5="Yes",0.05,0) +IF(J5="Yes",0.05,0) +IF(K5="Yes",0.15,0) +IF(L5="Yes",0.3,0) -> 1 | E5: Yes | F5: Yes | G5: Yes | H5: Yes | I5: Yes | J5: Yes | K5: Yes | L5: Yes
A6: https://4ammedia.zendesk.com/agent/tickets/226879 | B6: 46217 | C6: =IF(B6="", "", TEXT(B6, "ddd")) -> Tue | D6: =IF(E6="Yes",0.05,0) +IF(F6="Yes",0.1,0) +IF(G6="Yes",0.15,0) +IF(H6="Yes",0.15,0) +IF(I6="Yes",0.05,0) +IF(J6="Yes",0.05,0) +IF(K6="Yes",0.15,0) +IF(L6="Yes",0.3,0) -> 1 | E6: Yes | F6: Yes | G6: Yes | H6: Yes | I6: Yes | J6: Yes | K6: Yes | L6: Yes
A7: https://4ammedia.zendesk.com/agent/tickets/226958 | B7: 46217 | C7: =IF(B7="", "", TEXT(B7, "ddd")) -> Tue | D7: =IF(E7="Yes",0.05,0) +IF(F7="Yes",0.1,0) +IF(G7="Yes",0.15,0) +IF(H7="Yes",0.15,0) +IF(I7="Yes",0.05,0) +IF(J7="Yes",0.05,0) +IF(K7="Yes",0.15,0) +IF(L7="Yes",0.3,0) -> 1 | E7: Yes | F7: Yes | G7: Yes | H7: Yes | I7: Yes | J7: Yes | K7: Yes | L7: Yes
A8: https://4ammedia.zendesk.com/agent/tickets/226976 | B8: 46217 | C8: =IF(B8="", "", TEXT(B8, "ddd")) -> Tue | D8: =IF(E8="Yes",0.05,0) +IF(F8="Yes",0.1,0) +IF(G8="Yes",0.15,0) +IF(H8="Yes",0.15,0) +IF(I8="Yes",0.05,0) +IF(J8="Yes",0.05,0) +IF(K8="Yes",0.15,0) +IF(L8="Yes",0.3,0) -> 1 | E8: Yes | F8: Yes | G8: Yes | H8: Yes | I8: Yes | J8: Yes | K8: Yes | L8: Yes
A9: https://4ammedia.zendesk.com/agent/tickets/229944 | B9: 46219 | C9: =IF(B9="", "", TEXT(B9, "ddd")) -> Thu | D9: =IF(E9="Yes",0.05,0) +IF(F9="Yes",0.1,0) +IF(G9="Yes",0.15,0) +IF(H9="Yes",0.15,0) +IF(I9="Yes",0.05,0) +IF(J9="Yes",0.05,0) +IF(K9="Yes",0.15,0) +IF(L9="Yes",0.3,0) -> 1 | E9: Yes | F9: Yes | G9: Yes | H9: Yes | I9: Yes | J9: Yes | K9: Yes | L9: Yes
A10: https://4ammedia.zendesk.com/agent/tickets/229987 | B10: 46219 | C10: =IF(B10="", "", TEXT(B10, "ddd")) -> Thu | D10: =IF(E10="Yes",0.05,0) +IF(F10="Yes",0.1,0) +IF(G10="Yes",0.15,0) +IF(H10="Yes",0.15,0) +IF(I10="Yes",0.05,0) +IF(J10="Yes",0.05,0) +IF(K10="Yes",0.15,0) +IF(L10="Yes",0.3,0) -> 1 | E10: Yes | F10: Yes | G10: Yes | H10: Yes | I10: Yes | J10: Yes | K10: Yes | L10: Yes
A11: https://4ammedia.zendesk.com/agent/tickets/230022 | B11: 46219 | C11: =IF(B11="", "", TEXT(B11, "ddd")) -> Thu | D11: =IF(E11="Yes",0.05,0) +IF(F11="Yes",0.1,0) +IF(G11="Yes",0.15,0) +IF(H11="Yes",0.15,0) +IF(I11="Yes",0.05,0) +IF(J11="Yes",0.05,0) +IF(K11="Yes",0.15,0) +IF(L11="Yes",0.3,0) -> 1 | E11: Yes | F11: Yes | G11: Yes | H11: Yes | I11: Yes | J11: Yes | K11: Yes | L11: Yes
A12: https://4ammedia.zendesk.com/agent/tickets/232305 | B12: 46220 | C12: =IF(B12="", "", TEXT(B12, "ddd")) -> Fri | D12: =IF(E12="Yes",0.05,0) +IF(F12="Yes",0.1,0) +IF(G12="Yes",0.15,0) +IF(H12="Yes",0.15,0) +IF(I12="Yes",0.05,0) +IF(J12="Yes",0.05,0) +IF(K12="Yes",0.15,0) +IF(L12="Yes",0.3,0) -> 1 | E12: Yes | F12: Yes | G12: Yes | H12: Yes | I12: Yes | J12: Yes | K12: Yes | L12: Yes
A13: https://4ammedia.zendesk.com/agent/tickets/232580 | B13: 46220 | C13: =IF(B13="", "", TEXT(B13, "ddd")) -> Fri | D13: =IF(E13="Yes",0.05,0) +IF(F13="Yes",0.1,0) +IF(G13="Yes",0.15,0) +IF(H13="Yes",0.15,0) +IF(I13="Yes",0.05,0) +IF(J13="Yes",0.05,0) +IF(K13="Yes",0.15,0) +IF(L13="Yes",0.3,0) -> 1 | E13: Yes | F13: Yes | G13: Yes | H13: Yes | I13: Yes | J13: Yes | K13: Yes | L13: Yes
A14: https://4ammedia.zendesk.com/agent/tickets/232772 | B14: 46220 | C14: =IF(B14="", "", TEXT(B14, "ddd")) -> Fri | D14: =IF(E14="Yes",0.05,0) +IF(F14="Yes",0.1,0) +IF(G14="Yes",0.15,0) +IF(H14="Yes",0.15,0) +IF(I14="Yes",0.05,0) +IF(J14="Yes",0.05,0) +IF(K14="Yes",0.15,0) +IF(L14="Yes",0.3,0) -> 1 | E14: Yes | F14: Yes | G14: Yes | H14: Yes | I14: Yes | J14: Yes | K14: Yes | L14: Yes
A15: https://4ammedia.zendesk.com/agent/tickets/233703 | B15: 46221 | C15: =IF(B15="", "", TEXT(B15, "ddd")) -> Sat | D15: =IF(E15="Yes",0.05,0) +IF(F15="Yes",0.1,0) +IF(G15="Yes",0.15,0) +IF(H15="Yes",0.15,0) +IF(I15="Yes",0.05,0) +IF(J15="Yes",0.05,0) +IF(K15="Yes",0.15,0) +IF(L15="Yes",0.3,0) -> 0
A16: https://4ammedia.zendesk.com/agent/tickets/233776 | B16: 46221 | C16: =IF(B16="", "", TEXT(B16, "ddd")) -> Sat | D16: =IF(E16="Yes",0.05,0) +IF(F16="Yes",0.1,0) +IF(G16="Yes",0.15,0) +IF(H16="Yes",0.15,0) +IF(I16="Yes",0.05,0) +IF(J16="Yes",0.05,0) +IF(K16="Yes",0.15,0) +IF(L16="Yes",0.3,0) -> 0
A17: https://4ammedia.zendesk.com/agent/tickets/233878 | B17: 46221 | C17: =IF(B17="", "", TEXT(B17, "ddd")) -> Sat | D17: =IF(E17="Yes",0.05,0) +IF(F17="Yes",0.1,0) +IF(G17="Yes",0.15,0) +IF(H17="Yes",0.15,0) +IF(I17="Yes",0.05,0) +IF(J17="Yes",0.05,0) +IF(K17="Yes",0.15,0) +IF(L17="Yes",0.3,0) -> 0
C18: Final QA Score | D18: =AVERAGE(D3:D17) -> 0.8 | L18: Final QA Score | M18: =SUM(M3:M17)/75*0.1 -> 0
A19: Week (July 20, - July 26,2026)
A20: Ticket Link | B20: Date | C20: Day | D20: SCORE | E20: Notes and Tagging(internal Note and Sticky Note) 5% | F20: COURTESY & EMPATHY 15% | G20: TONE OF VOICE & ELOQUENCE 20% | H20: CALL CONTROL 15% | I20: VERIFICATION 5% | J20: PROBING 5% | K20: MASTERY OF INFORMATION 15% | L20: RESOLUTION 20% | M20: Average | N20: NOTES
A21: https://4ammedia.zendesk.com/agent/tickets/236767 | B21: 46223 | C21: =IF(B21="", "", TEXT(B21, "ddd")) -> Mon | D21: =IF(E21="Yes",0.05,0) +IF(F21="Yes",0.1,0) +IF(G21="Yes",0.15,0) +IF(H21="Yes",0.15,0) +IF(I21="Yes",0.05,0) +IF(J21="Yes",0.05,0) +IF(K21="Yes",0.15,0) +IF(L21="Yes",0.3,0) -> 1 | E21: Yes | F21: Yes | G21: Yes | H21: Yes | I21: Yes | J21: Yes | K21: Yes | L21: Yes
A22: https://4ammedia.zendesk.com/agent/tickets/236819 | B22: 46223 | C22: =IF(B22="", "", TEXT(B22, "ddd")) -> Mon | D22: =IF(E22="Yes",0.05,0) +IF(F22="Yes",0.1,0) +IF(G22="Yes",0.15,0) +IF(H22="Yes",0.15,0) +IF(I22="Yes",0.05,0) +IF(J22="Yes",0.05,0) +IF(K22="Yes",0.15,0) +IF(L22="Yes",0.3,0) -> 1 | E22: Yes | F22: Yes | G22: Yes | H22: Yes | I22: Yes | J22: Yes | K22: Yes | L22: Yes
A23: https://4ammedia.zendesk.com/agent/tickets/236994 | B23: 46223 | C23: =IF(B23="", "", TEXT(B23, "ddd")) -> Mon | D23: =IF(E23="Yes",0.05,0) +IF(F23="Yes",0.1,0) +IF(G23="Yes",0.15,0) +IF(H23="Yes",0.15,0) +IF(I23="Yes",0.05,0) +IF(J23="Yes",0.05,0) +IF(K23="Yes",0.15,0) +IF(L23="Yes",0.3,0) -> 1 | E23: Yes | F23: Yes | G23: Yes | H23: Yes | I23: Yes | J23: Yes | K23: Yes | L23: Yes
